Workbook
Name Customer_Name: Fruit_Sales_Data!$B$6:$B$53
Name Customer_Name: Linking_Data!$C$4:$C$60
Name Customer_Name: #REF!
Name Price_Per_Item: Fruit_Sales_Data!$D$6:$D$53
Name Price_Per_Item: Linking_Data!#REF!
Name Price_Per_Item: #REF!
Name Quantity: Fruit_Sales_Data!$C$6:$C$53
Name Quantity: Linking_Data!$D$4:$D$60
Name Quantity: #REF!
Name Sales_Tax: Fruit_Sales_Data!$F$6:$F$53
Name Sales_Tax: Linking_Data!$F$6:$F$60
Name Sales_Tax: #REF!
Name Total: Fruit_Sales_Data!$E$6:$E$53
Name Total: Linking_Data!$E$6:$E$60
Name Total: #REF!
Name Total__inc_Tax: Fruit_Sales_Data!#REF!
Name Total__inc_Tax: Linking_Data!#REF!
Name Total__inc_Tax: #REF!

Sheet EXERCISE 08
A1: EXERCISE 08
A3: PASTE OPTIONS
A13: LINKING DATA
A25: 3D REFERENCING

Sheet Fruit_Sales_Data
A3: Fruit Sales Data | F3: Paste with Column Widths Preserved | K3: Paste Values Only
A5: Fruit | B5: Quantity | C5: Price Per Item | D5: Total | F5: Fruit | G5: Quantity | H5: Price Per Item | I5: Total | K5: Fruit | L5: Quantity | M5: Price Per Item | N5: Total
A6: Apple | B6: 15 | C6: 2 | D6: =SUM(B6*C6) -> 30 | F6: Apple | G6: 15 | H6: 2 | I6: =SUM(G6*H6) -> 30 | K6: Apple | L6: 15 | M6: 2 | N6: 30
A7: Orange | B7: 23 | C7: 1.4 | D7: =SUM(B7*C7) -> 32.2 | F7: Orange | G7: 23 | H7: 1.4 | I7: =SUM(G7*H7) -> 32.2 | K7: Orange | L7: 23 | M7: 1.4 | N7: 32.2
A8: Lemon | B8: 45 | C8: 1.5 | D8: =SUM(B8*C8) -> 67.5 | F8: Lemon | G8: 45 | H8: 1.5 | I8: =SUM(G8*H8) -> 67.5 | K8: Lemon | L8: 45 | M8: 1.5 | N8: 67.5
A9: Banana | B9: 25 | C9: 2.5 | D9: =SUM(B9*C9) -> 62.5 | F9: Banana | G9: 25 | H9: 2.5 | I9: =SUM(G9*H9) -> 62.5 | K9: Banana | L9: 25 | M9: 2.5 | N9: 62.5
A10: Plum | B10: 56 | C10: 3 | D10: =SUM(B10*C10) -> 168 | F10: Plum | G10: 56 | H10: 3 | I10: =SUM(G10*H10) -> 168 | K10: Plum | L10: 56 | M10: 3 | N10: 168
A11: Strawberry | B11: 45 | C11: 4 | D11: =SUM(B11*C11) -> 180 | F11: Strawberry | G11: 45 | H11: 4 | I11: =SUM(G11*H11) -> 180 | K11: Strawberry | L11: 45 | M11: 4 | N11: 180
A14: Transpose Data
A15: Fruit | B15: Apple | C15: Orange | D15: Lemon | E15: Banana | F15: Plum | G15: Strawberry
A16: Quantity | B16: 15 | C16: 23 | D16: 45 | E16: 25 | F16: 56 | G16: 45
A17: Price Per Item | B17: 2 | C17: 1.4 | D17: 1.5 | E17: 2.5 | F17: 3 | G17: 4
A18: Total | B18: =SUM(B16*B17) -> 30 | C18: =SUM(C16*C17) -> 32.2 | D18: =SUM(D16*D17) -> 67.5 | E18: =SUM(E16*E17) -> 62.5 | F18: =SUM(F16*F17) -> 168 | G18: =SUM(G16*G17) -> 180

Sheet Linking_Data
B1: Client List: Revenue vs Profit
B3: Client | C3: Revenue | D3: Profit
B4: Company A | C4: 9598 | D4: 7598
B5: Company A | C5: 11496 | D5: 9496
B6: Company A | C6: 8314 | D6: 6314
B7: Company A | C7: 5929 | D7: 3929
B8: Company A | C8: 9273 | D8: 7273
B9: Company A | C9: 5114 | D9: 3114
B10: Company A | C10: 14472 | D10: 12472
B11: Company A Total | C11: =SUBTOTAL(9,C4:C10) -> 64196 | D11: =SUBTOTAL(9,D4:D10) -> 50196
B12: Company B | C12: 12753 | D12: 10753
B13: Company B | C13: 8190 | D13: 6190
B14: Company B | C14: 7751 | D14: 5751
B15: Company B | C15: 14855 | D15: 12855
B16: Company B | C16: 9008 | D16: 7008
B17: Company B | C17: 5284 | D17: 3284
B18: Company B Total | C18: =SUBTOTAL(9,C12:C17) -> 57841 | D18: =SUBTOTAL(9,D12:D17) -> 45841
B19: Company C | C19: 8179 | D19: 6179
B20: Company C | C20: 10077 | D20: 8077
B21: Company C | C21: 5720 | D21: 3720
B22: Company C | C22: 8976 | D22: 6976
B23: Company C | C23: 12459 | D23: 10459
B24: Company C | C24: 14213 | D24: 12213
B25: Company C Total | C25: =SUBTOTAL(9,C19:C24) -> 59624 | D25: =SUBTOTAL(9,D19:D24) -> 47624
B26: Company D | C26: 7789 | D26: 5789
B27: Company D | C27: 10230 | D27: 8230
B28: Company D | C28: 10475 | D28: 8475
B29: Company D | C29: 12864 | D29: 10864
B30: Company D | C30: 8429 | D30: 6429
B31: Company D Total | C31: =SUBTOTAL(9,C26:C30) -> 49787 | D31: =SUBTOTAL(9,D26:D30) -> 39787
B32: Company E | C32: 8629 | D32: 6629
B33: Company E | C33: 7463 | D33: 5463
B34: Company E | C34: 5964 | D34: 3964
B35: Company E | C35: 7929 | D35: 5929
B36: Company E | C36: 13712 | D36: 11712
B37: Company E | C37: 11382 | D37: 9382
B38: Company E | C38: 8867 | D38: 6867
B39: Company E Total | C39: =SUBTOTAL(9,C32:C38) -> 63946 | D39: =SUBTOTAL(9,D32:D38) -> 49946
B40: Company F | C40: 14258 | D40: 12258
B41: Company F | C41: 13024 | D41: 11024
...

Sheet Summary
A1: Summary Table
A3: Client | B3: Total Profit
A4: Company A | B4: =Linking_Data!D11 -> 50196
A5: Company B | B5: =Linking_Data!D18 -> 45841
A6: Company C | B6: =Linking_Data!D25 -> 47624
A7: Company D | B7: =Linking_Data!D31 -> 39787
A8: Company E | B8: =Linking_Data!D39 -> 49946
A9: Company F | B9: =Linking_Data!D48 -> 78144

Sheet TechWorld_Sales
A1: TECHWORLD SALES (JAN - DEC 2019)
B3: North | C3: South | D3: East | E3: West
A4: Jan | B4: 18744 | C4: 7730 | D4: 7146 | E4: 12540
A5: Feb | B5: 12448 | C5: 7485 | D5: 17200 | E5: 19544
A6: Mar | B6: 18862 | C6: 11727 | D6: 19337 | E6: 8721
A7: Apr | B7: 14402 | C7: 12514 | D7: 16523 | E7: 11560

Sheet MicroWorld_Sales
A1: MICROWORLD SALES (JAN - APR 2019)
B3: North | C3: South | D3: East | E3: West
A4: Jan | B4: 9966 | C4: 4705 | D4: 9441 | E4: 5923
A5: Feb | B5: 8918 | C5: 7901 | D5: 3968 | E5: 3578
A6: Mar | B6: 7028 | C6: 7367 | D6: 4282 | E6: 5162
A7: Apr | B7: 5733 | C7: 5617 | D7: 2064 | E7: 7971

Sheet Tech4U_Sales
A1: TECH4U SALES (JAN - APR 2019)
B3: North | C3: South | D3: East | E3: West
A4: Jan | B4: 8748 | C4: 13423 | D4: 13083 | E4: 6221
A5: Feb | B5: 7125 | C5: 8779 | D5: 10439 | E5: 9747
A6: Mar | B6: 9312 | C6: 12178 | D6: 7359 | E6: 11162
A7: Apr | B7: 8269 | C7: 11024 | D7: 12200 | E7: 9973

Sheet Joplins_Sales
A1: JOPLINS SALES (JAN - APR 2019)
B3: North | C3: South | D3: East | E3: West
A4: Jan | B4: 10821 | C4: 24901 | D4: 17393 | E4: 21209
A5: Feb | B5: 11682 | C5: 11838 | D5: 12612 | E5: 16384
A6: Mar | B6: 11435 | C6: 14716 | D6: 18020 | E6: 10131
A7: Apr | B7: 23430 | C7: 16119 | D7: 24000 | E7: 22991

Sheet Total_Sales
A1: TOTAL SALES (JAN - APR 2019)
B3: North | C3: South | D3: East | E3: West
A4: Jan | B4: =SUM(TechWorld_Sales:Joplins_Sales!B4) -> 48279 | C4: =SUM(TechWorld_Sales:Joplins_Sales!C4) -> 50759 | D4: =SUM(TechWorld_Sales:Joplins_Sales!D4) -> 47063 | E4: =SUM(TechWorld_Sales:Joplins_Sales!E4) -> 45893
A5: Feb | B5: =SUM(TechWorld_Sales:Joplins_Sales!B5) -> 40173 | C5: =SUM(TechWorld_Sales:Joplins_Sales!C5) -> 36003 | D5: =SUM(TechWorld_Sales:Joplins_Sales!D5) -> 44219 | E5: =SUM(TechWorld_Sales:Joplins_Sales!E5) -> 49253
A6: Mar | B6: =SUM(TechWorld_Sales:Joplins_Sales!B6) -> 46637 | C6: =SUM(TechWorld_Sales:Joplins_Sales!C6) -> 45988 | D6: =SUM(TechWorld_Sales:Joplins_Sales!D6) -> 48998 | E6: =SUM(TechWorld_Sales:Joplins_Sales!E6) -> 35176
A7: Apr | B7: =SUM(TechWorld_Sales:Joplins_Sales!B7) -> 51834 | C7: =SUM(TechWorld_Sales:Joplins_Sales!C7) -> 45274 | D7: =SUM(TechWorld_Sales:Joplins_Sales!D7) -> 54787 | E7: =SUM(TechWorld_Sales:Joplins_Sales!E7) -> 52495
